<?xml version="1.0" ?>
<robot name="z-bot2_fe_urdf">
  <joint name="imu" type="fixed">
    <origin xyz="0.041000 0.010001 -0.030001" rpy="1.570000 0 -1.570000"/>
    <parent link="Z-BOT2_MASTER-BODY-SKELETON"/>
    <child link="IMU"/>
  </joint>
  <joint name="left_shoulder_yaw" type="revolute">
    <origin xyz="0.060002 -0.011000 -0.010001" rpy="1.570000 0 -3.140000"/>
    <parent link="Z-BOT2_MASTER-BODY-SKELETON"/>
    <child link="Z-BOT2-MASTER-SHOULDER2"/>
    <limit effort="2" velocity="2" lower="-1.047198" upper="0"/>
    <axis xyz="0 0 1"/>
  </joint>
  <joint name="right_shoulder_yaw" type="revolute">
    <origin xyz="-0.060000 -0.011000 -0.010001" rpy="-1.570000 0 0"/>
    <parent link="Z-BOT2_MASTER-BODY-SKELETON"/>
    <child link="Z-BOT2-MASTER-SHOULDER2_2"/>
    <limit effort="2" velocity="2" lower="0" upper="1.047198"/>
    <axis xyz="0 0 1"/>
  </joint>
  <joint name="left_hip_yaw" type="revolute">
    <origin xyz="0.040000 0.009998 -0.079000" rpy="3.140000 0 3.140000"/>
    <parent link="Z-BOT2_MASTER-BODY-SKELETON"/>
    <child link="U-HIP-L"/>
    <limit effort="2" velocity="2" lower="-1.047198" upper="1.047198"/>
    <axis xyz="0 0 1"/>
  </joint>
  <joint name="right_hip_yaw" type="revolute">
    <origin xyz="-0.040000 0.009998 -0.079000" rpy="3.140000 0 3.140000"/>
    <parent link="Z-BOT2_MASTER-BODY-SKELETON"/>
    <child link="U-HIP-R"/>
    <limit effort="2" velocity="2" lower="-1.047198" upper="1.047198"/>
    <axis xyz="0 0 1"/>
  </joint>
  <joint name="left_shoulder_pitch" type="revolute">
    <origin xyz="-0.020845 -0.004900 0.018800" rpy="-1.570796 0 -1.570796"/>
    <parent link="Z-BOT2-MASTER-SHOULDER2"/>
    <child link="3215_1Flange"/>
    <limit effort="2" velocity="2" lower="-2.967060" upper="3.141593"/>
    <axis xyz="0 0 1"/>
  </joint>
  <joint name="right_shoulder_pitch" type="revolute">
    <origin xyz="-0.020845 0.004900 0.018800" rpy="1.570796 0 1.570796"/>
    <parent link="Z-BOT2-MASTER-SHOULDER2_2"/>
    <child link="3215_1Flange_2"/>
    <limit effort="2" velocity="2" lower="-3.141593" upper="2.967060"/>
    <axis xyz="0 0 1"/>
  </joint>
  <joint name="left_hip_roll" type="revolute">
    <origin xyz="0 0.017700 0.056400" rpy="-1.570796 0 0"/>
    <parent link="U-HIP-L"/>
    <child link="3215_BothFlange_5"/>
    <limit effort="2" velocity="2" lower="-0.174533" upper="1.570796"/>
    <axis xyz="0 0 -1.0"/>
  </joint>
  <joint name="right_hip_roll" type="revolute">
    <origin xyz="0 -0.017700 0.056400" rpy="-1.570796 0 -3.141593"/>
    <parent link="U-HIP-R"/>
    <child link="3215_BothFlange_6"/>
    <limit effort="2" velocity="2" lower="-1.570796" upper="0.174533"/>
    <axis xyz="0 0 1"/>
  </joint>
  <joint name="left_hip_pitch" type="revolute">
    <origin xyz="-0.006400 -0.032000 -0.017900" rpy="1.570796 0 -1.570796"/>
    <parent link="3215_BothFlange_5"/>
    <child link="3215_BothFlange_9"/>
    <limit effort="2" velocity="2" lower="-1.570796" upper="1.570796"/>
    <axis xyz="0 0 1"/>
  </joint>
  <joint name="right_hip_pitch" type="revolute">
    <origin xyz="-0.006400 -0.032000 -0.018900" rpy="1.570796 0 -1.570796"/>
    <parent link="3215_BothFlange_6"/>
    <child link="3215_BothFlange_10"/>
    <limit effort="2" velocity="2" lower="-1.570796" upper="1.570796"/>
    <axis xyz="0 0 1"/>
  </joint>
  <joint name="left_elbow" type="revolute">
    <origin xyz="0.092984 0.019800 -0.018600" rpy="1.570796 0 3.141593"/>
    <parent link="3215_1Flange"/>
    <child link="R-ARM-MIRROR-1"/>
    <limit effort="2" velocity="2" lower="-1.570796" upper="1.570796"/>
    <axis xyz="0 0 -1"/>
  </joint>
  <joint name="right_elbow" type="revolute">
    <origin xyz="0.092984 -0.019800 -0.018600" rpy="-1.570796 -1.570796 0"/>
    <parent link="3215_1Flange_2"/>
    <child link="L-ARM-MIRROR_1"/>
    <limit effort="2" velocity="2" lower="-1.570796" upper="1.570796"/>
    <axis xyz="0 0 1"/>
  </joint>
  <joint name="left_knee" type="revolute">
    <origin xyz="0.100000 0.010000 -0.001260" rpy="0 0 0"/>
    <parent link="3215_BothFlange_9"/>
    <child link="3215_BothFlange_13"/>
    <limit effort="2" velocity="2" lower="-1.221731" upper="2.792527"/>
    <axis xyz="0 0 1"/>
  </joint>
  <joint name="right_knee" type="revolute">
    <origin xyz="0.100000 -0.010000 -0.001260" rpy="0 0 0"/>
    <parent link="3215_BothFlange_10"/>
    <child link="3215_BothFlange_14"/>
    <limit effort="2" velocity="2" lower="-2.792527" upper="1.221731"/>
    <axis xyz="0 0 1"/>
  </joint>
  <joint name="left_gripper" type="revolute">
    <origin xyz="-0.066206 -0.011778 0.001260" rpy="3.141593 0 1.919862"/>
    <parent link="R-ARM-MIRROR-1"/>
    <child link="FINGER_1"/>
    <limit effort="2" velocity="2" lower="-0.349066" upper="0.698132"/>
    <axis xyz="0 0 1"/>
  </joint>
  <joint name="right_gripper" type="revolute">
    <origin xyz="-0.011778 0.066206 -0.001260" rpy="0 0 0.349066"/>
    <parent link="L-ARM-MIRROR_1"/>
    <child link="FINGER_1_2"/>
    <limit effort="2" velocity="2" lower="-0.698132" upper="0.349066"/>
    <axis xyz="0 0 1"/>
  </joint>
  <joint name="left_ankle" type="revolute">
    <origin xyz="0.100000 0 0.000800" rpy="-3.141593 0 1.570796"/>
    <parent link="3215_BothFlange_13"/>
    <child link="FOOT"/>
    <limit effort="2" velocity="2" lower="-1.570796" upper="1.570796"/>
    <axis xyz="0 0 1"/>
  </joint>
  <joint name="right_ankle" type="revolute">
    <origin xyz="0.100000 0 0.001000" rpy="-3.141593 0 -1.570796"/>
    <parent link="3215_BothFlange_14"/>
    <child link="FOOT_2"/>
    <limit effort="2" velocity="2" lower="-1.570796" upper="1.570796"/>
    <axis xyz="0 0 1"/>
  </joint>
  <link name="Z-BOT2_MASTER-BODY-SKELETON">
    <visual name="Z-BOT2_MASTER-BODY-SKELETON_visual">
      <origin xyz="0 0 0" rpy="0 0 0"/>
      <geometry name="Z-BOT2_MASTER-BODY-SKELETON_geometry">
        <mesh filename="meshes/Z-BOT2_MASTER-BODY-SKELETON.stl"/>
      </geometry>
      <material name="Z-BOT2_MASTER-BODY-SKELETON_material">
        <color rgba="0.494118 0.623529 0.749020 1"/>
      </material>
    </visual>
    <collision name="Z-BOT2_MASTER-BODY-SKELETON.collision">
      <origin xyz="0 0 0" rpy="0 0 0"/>
      <geometry name="Z-BOT2_MASTER-BODY-SKELETON_collision_geometry">
        <mesh filename="meshes/Z-BOT2_MASTER-BODY-SKELETON.collision.stl"/>
      </geometry>
    </collision>
    <inertial name="Z-BOT2_MASTER-BODY-SKELETON_inertial">
      <mass value="1.546392"/>
      <inertia ixx="0.004795" iyy="0.005455" izz="0.002588" ixy="0.000008" ixz="0.000010" iyz="-0.000041"/>
      <origin xyz="-0.000189 0.010193 -0.031201" rpy="0 0 0"/>
    </inertial>
  </link>
  <link name="IMU">
    <visual name="IMU_visual">
      <origin xyz="0 0 0" rpy="0 0 0"/>
      <geometry name="IMU_geometry">
        <mesh filename="meshes/IMU.stl"/>
      </geometry>
      <material name="IMU_material">
        <color rgba="0 1 0 1"/>
      </material>
    </visual>
    <inertial name="IMU_inertial">
      <mass value="0.001887"/>
      <inertia ixx="0.000001" iyy="0.000001" izz="0.000001" ixy="0" ixz="0" iyz="0"/>
      <origin xyz="-0.010000 -0.007500 -0.001235" rpy="0 0 0"/>
    </inertial>
  </link>
  <link name="Z-BOT2-MASTER-SHOULDER2">
    <visual name="Z-BOT2-MASTER-SHOULDER2_visual">
      <origin xyz="0 0 0" rpy="0 0 0"/>
      <geometry name="Z-BOT2-MASTER-SHOULDER2_geometry">
        <mesh filename="meshes/Z-BOT2-MASTER-SHOULDER2.stl"/>
      </geometry>
      <material name="Z-BOT2-MASTER-SHOULDER2_material">
        <color rgba="0.364706 0.360784 0.749020 1"/>
      </material>
    </visual>
    <inertial name="Z-BOT2-MASTER-SHOULDER2_inertial">
      <mass value="0.024098"/>
      <inertia ixx="0.000007" iyy="0.000008" izz="0.000003" ixy="0" ixz="0" iyz="0"/>
      <origin xyz="-0.012788 0.001374 0.018800" rpy="0 0 0"/>
    </inertial>
  </link>
  <link name="Z-BOT2-MASTER-SHOULDER2_2">
    <visual name="Z-BOT2-MASTER-SHOULDER2_visual_2">
      <origin xyz="0 0 0" rpy="0 0 0"/>
      <geometry name="Z-BOT2-MASTER-SHOULDER2_geometry_2">
        <mesh filename="meshes/Z-BOT2-MASTER-SHOULDER2_2.stl"/>
      </geometry>
      <material name="Z-BOT2-MASTER-SHOULDER2_material_2">
        <color rgba="0.364706 0.360784 0.749020 1"/>
      </material>
    </visual>
    <inertial name="Z-BOT2-MASTER-SHOULDER2_inertial_2">
      <mass value="0.024098"/>
      <inertia ixx="0.000007" iyy="0.000008" izz="0.000003" ixy="0" ixz="0" iyz="0"/>
      <origin xyz="-0.012788 -0.001374 0.018800" rpy="0 0 0"/>
    </inertial>
  </link>
  <link name="U-HIP-L">
    <visual name="U-HIP-L_visual">
      <origin xyz="0 0 0" rpy="0 0 0"/>
      <geometry name="U-HIP-L_geometry">
        <mesh filename="meshes/U-HIP-L.stl"/>
      </geometry>
      <material name="U-HIP-L_material">
        <color rgba="0.768627 0.886275 0.952941 1"/>
      </material>
    </visual>
    <inertial name="U-HIP-L_inertial">
      <mass value="0.047132"/>
      <inertia ixx="0.000029" iyy="0.000030" izz="0.000019" ixy="0.000004" ixz="-0.000008" iyz="0.000004"/>
      <origin xyz="-0.001161 -0.004396 0.035396" rpy="0 0 0"/>
    </inertial>
  </link>
  <link name="U-HIP-R">
    <visual name="U-HIP-R_visual">
      <origin xyz="0 0 0" rpy="0 0 0"/>
      <geometry name="U-HIP-R_geometry">
        <mesh filename="meshes/U-HIP-R.stl"/>
      </geometry>
      <material name="U-HIP-R_material">
        <color rgba="0.768627 0.886275 0.952941 1"/>
      </material>
    </visual>
    <inertial name="U-HIP-R_inertial">
      <mass value="0.047132"/>
      <inertia ixx="0.000029" iyy="0.000030" izz="0.000019" ixy="-0.000004" ixz="0.000008" iyz="0.000004"/>
      <origin xyz="0.001161 -0.004396 0.035396" rpy="0 0 0"/>
    </inertial>
  </link>
  <link name="3215_1Flange">
    <visual name="3215_1Flange_visual">
      <origin xyz="0 0 0" rpy="0 0 0"/>
      <geometry name="3215_1Flange_geometry">
        <mesh filename="meshes/3215_1Flange.stl"/>
      </geometry>
      <material name="3215_1Flange_material">
        <color rgba="0.749020 0.498039 0.725490 1"/>
      </material>
    </visual>
    <collision name="3215_1Flange.collision">
      <origin xyz="0 0 0" rpy="0 0 0"/>
      <geometry name="3215_1Flange_collision_geometry">
        <mesh filename="meshes/3215_1Flange.collision.stl"/>
      </geometry>
    </collision>
    <inertial name="3215_1Flange_inertial">
      <mass value="0.181960"/>
      <inertia ixx="0.000054" iyy="0.000228" izz="0.000232" ixy="-0.000004" ixz="0.000006" iyz="0"/>
      <origin xyz="0.033642 0.000438 -0.019963" rpy="0 0 0"/>
    </inertial>
  </link>
  <link name="3215_1Flange_2">
    <visual name="3215_1Flange_visual_2">
      <origin xyz="0 0 0" rpy="0 0 0"/>
      <geometry name="3215_1Flange_geometry_2">
        <mesh filename="meshes/3215_1Flange_2.stl"/>
      </geometry>
      <material name="3215_1Flange_material_2">
        <color rgba="0.749020 0.498039 0.725490 1"/>
      </material>
    </visual>
    <collision name="3215_1Flange.collision_2">
      <origin xyz="0 0 0" rpy="0 0 0"/>
      <geometry name="3215_1Flange_collision_geometry_2">
        <mesh filename="meshes/3215_1Flange_2.collision.stl"/>
      </geometry>
    </collision>
    <inertial name="3215_1Flange_inertial_2">
      <mass value="0.181960"/>
      <inertia ixx="0.000054" iyy="0.000228" izz="0.000232" ixy="0.000004" ixz="0.000006" iyz="0"/>
      <origin xyz="0.033642 -0.000433 -0.019968" rpy="0 0 0"/>
    </inertial>
  </link>
  <link name="3215_BothFlange_5">
    <visual name="3215_BothFlange_visual_5">
      <origin xyz="0 0 0" rpy="0 0 0"/>
      <geometry name="3215_BothFlange_geometry_5">
        <mesh filename="meshes/3215_BothFlange_5.stl"/>
      </geometry>
      <material name="3215_BothFlange_material_5">
        <color rgba="1 0 0 1"/>
      </material>
    </visual>
    <inertial name="3215_BothFlange_inertial_5">
      <mass value="0.068295"/>
      <inertia ixx="0.000019" iyy="0.000024" izz="0.000025" ixy="0" ixz="0" iyz="0"/>
      <origin xyz="0.012332 -0.008997 -0.018508" rpy="0 0 0"/>
    </inertial>
  </link>
  <link name="3215_BothFlange_6">
    <visual name="3215_BothFlange_visual_6">
      <origin xyz="0 0 0" rpy="0 0 0"/>
      <geometry name="3215_BothFlange_geometry_6">
        <mesh filename="meshes/3215_BothFlange_6.stl"/>
      </geometry>
      <material name="3215_BothFlange_material_6">
        <color rgba="1 0 0 1"/>
      </material>
    </visual>
    <inertial name="3215_BothFlange_inertial_6">
      <mass value="0.068295"/>
      <inertia ixx="0.000019" iyy="0.000024" izz="0.000025" ixy="0" ixz="0" iyz="0"/>
      <origin xyz="0.012332 -0.008983 -0.017811" rpy="0 0 0"/>
    </inertial>
  </link>
  <link name="3215_BothFlange_9">
    <visual name="3215_BothFlange_visual_9">
      <origin xyz="0 0 0" rpy="0 0 0"/>
      <geometry name="3215_BothFlange_geometry_9">
        <mesh filename="meshes/3215_BothFlange_9.stl"/>
      </geometry>
      <material name="3215_BothFlange_material_9">
        <color rgba="1 0 0 1"/>
      </material>
    </visual>
    <collision name="3215_BothFlange.collision_9">
      <origin xyz="0 0 0" rpy="0 0 0"/>
      <geometry name="3215_BothFlange_collision_geometry_9">
        <mesh filename="meshes/3215_BothFlange_9.collision.stl"/>
      </geometry>
    </collision>
    <inertial name="3215_BothFlange_inertial_9">
      <mass value="0.143337"/>
      <inertia ixx="0.000049" iyy="0.000148" izz="0.000128" ixy="0.000003" ixz="0.000002" iyz="0"/>
      <origin xyz="0.043662 -0.002857 -0.018525" rpy="0 0 0"/>
    </inertial>
  </link>
  <link name="3215_BothFlange_10">
    <visual name="3215_BothFlange_visual_10">
      <origin xyz="0 0 0" rpy="0 0 0"/>
      <geometry name="3215_BothFlange_geometry_10">
        <mesh filename="meshes/3215_BothFlange_10.stl"/>
      </geometry>
      <material name="3215_BothFlange_material_10">
        <color rgba="1 0 0 1"/>
      </material>
    </visual>
    <collision name="3215_BothFlange.collision_10">
      <origin xyz="0 0 0" rpy="0 0 0"/>
      <geometry name="3215_BothFlange_collision_geometry_10">
        <mesh filename="meshes/3215_BothFlange_10.collision.stl"/>
      </geometry>
    </collision>
    <inertial name="3215_BothFlange_inertial_10">
      <mass value="0.143337"/>
      <inertia ixx="0.000049" iyy="0.000148" izz="0.000128" ixy="-0.000003" ixz="0.000002" iyz="0"/>
      <origin xyz="0.043662 0.002863 -0.018537" rpy="0 0 0"/>
    </inertial>
  </link>
  <link name="R-ARM-MIRROR-1">
    <visual name="R-ARM-MIRROR-1_visual">
      <origin xyz="0 0 0" rpy="0 0 0"/>
      <geometry name="R-ARM-MIRROR-1_geometry">
        <mesh filename="meshes/R-ARM-MIRROR-1.stl"/>
      </geometry>
      <material name="R-ARM-MIRROR-1_material">
        <color rgba="0.647059 0.647059 0.647059 1"/>
      </material>
    </visual>
    <collision name="R-ARM-MIRROR-1.collision">
      <origin xyz="0 0 0" rpy="0 0 0"/>
      <geometry name="R-ARM-MIRROR-1_collision_geometry">
        <mesh filename="meshes/R-ARM-MIRROR-1.collision.stl"/>
      </geometry>
    </collision>
    <inertial name="R-ARM-MIRROR-1_inertial">
      <mass value="0.186073"/>
      <inertia ixx="0.000061" iyy="0.000218" izz="0.000201" ixy="0.000021" ixz="0" iyz="0.000002"/>
      <origin xyz="-0.051119 0.001150 -0.017743" rpy="0 0 0"/>
    </inertial>
  </link>
  <link name="L-ARM-MIRROR_1">
    <visual name="L-ARM-MIRROR_1_visual">
      <origin xyz="0 0 0" rpy="0 0 0"/>
      <geometry name="L-ARM-MIRROR_1_geometry">
        <mesh filename="meshes/L-ARM-MIRROR_1.stl"/>
      </geometry>
      <material name="L-ARM-MIRROR_1_material">
        <color rgba="0.627451 0.627451 0.627451 1"/>
      </material>
    </visual>
    <collision name="L-ARM-MIRROR_1.collision">
      <origin xyz="0 0 0" rpy="0 0 0"/>
      <geometry name="L-ARM-MIRROR_1_collision_geometry">
        <mesh filename="meshes/L-ARM-MIRROR_1.collision.stl"/>
      </geometry>
    </collision>
    <inertial name="L-ARM-MIRROR_1_inertial">
      <mass value="0.186073"/>
      <inertia ixx="0.000218" iyy="0.000061" izz="0.000201" ixy="-0.000021" ixz="-0.000002" iyz="0"/>
      <origin xyz="0.001144 0.051123 0.017764" rpy="0 0 0"/>
    </inertial>
  </link>
  <link name="3215_BothFlange_13">
    <visual name="3215_BothFlange_visual_13">
      <origin xyz="0 0 0" rpy="0 0 0"/>
      <geometry name="3215_BothFlange_geometry_13">
        <mesh filename="meshes/3215_BothFlange_13.stl"/>
      </geometry>
      <material name="3215_BothFlange_material_13">
        <color rgba="1 0 0 1"/>
      </material>
    </visual>
    <collision name="3215_BothFlange.collision_13">
      <origin xyz="0 0 0" rpy="0 0 0"/>
      <geometry name="3215_BothFlange_collision_geometry_13">
        <mesh filename="meshes/3215_BothFlange_13.collision.stl"/>
      </geometry>
    </collision>
    <inertial name="3215_BothFlange_inertial_13">
      <mass value="0.128213"/>
      <inertia ixx="0.000035" iyy="0.000154" izz="0.000145" ixy="0" ixz="0" iyz="0"/>
      <origin xyz="0.050000 0 -0.017988" rpy="0 0 0"/>
    </inertial>
  </link>
  <link name="3215_BothFlange_14">
    <visual name="3215_BothFlange_visual_14">
      <origin xyz="0 0 0" rpy="0 0 0"/>
      <geometry name="3215_BothFlange_geometry_14">
        <mesh filename="meshes/3215_BothFlange_14.stl"/>
      </geometry>
      <material name="3215_BothFlange_material_14">
        <color rgba="1 0 0 1"/>
      </material>
    </visual>
    <collision name="3215_BothFlange.collision_14">
      <origin xyz="0 0 0" rpy="0 0 0"/>
      <geometry name="3215_BothFlange_collision_geometry_14">
        <mesh filename="meshes/3215_BothFlange_14.collision.stl"/>
      </geometry>
    </collision>
    <inertial name="3215_BothFlange_inertial_14">
      <mass value="0.128213"/>
      <inertia ixx="0.000036" iyy="0.000155" izz="0.000145" ixy="0" ixz="0" iyz="0"/>
      <origin xyz="0.050000 0 -0.017888" rpy="0 0 0"/>
    </inertial>
  </link>
  <link name="FINGER_1">
    <visual name="FINGER_1_visual">
      <origin xyz="0 0 0" rpy="0 0 0"/>
      <geometry name="FINGER_1_geometry">
        <mesh filename="meshes/FINGER_1.stl"/>
      </geometry>
      <material name="FINGER_1_material">
        <color rgba="0.627451 0.627451 0.627451 1"/>
      </material>
    </visual>
    <collision name="FINGER_1.collision">
      <origin xyz="0 0 0" rpy="0 0 0"/>
      <geometry name="FINGER_1_collision_geometry">
        <mesh filename="meshes/FINGER_1.collision.stl"/>
      </geometry>
    </collision>
    <inertial name="FINGER_1_inertial">
      <mass value="0.044318"/>
      <inertia ixx="0.000023" iyy="0.000010" izz="0.000016" ixy="-0.000002" ixz="0" iyz="0"/>
      <origin xyz="-0.010671 -0.028985 0.018800" rpy="0 0 0"/>
    </inertial>
  </link>
  <link name="FINGER_1_2">
    <visual name="FINGER_1_visual_2">
      <origin xyz="0 0 0" rpy="0 0 0"/>
      <geometry name="FINGER_1_geometry_2">
        <mesh filename="meshes/FINGER_1_2.stl"/>
      </geometry>
      <material name="FINGER_1_material_2">
        <color rgba="0.627451 0.627451 0.627451 1"/>
      </material>
    </visual>
    <collision name="FINGER_1.collision_2">
      <origin xyz="0 0 0" rpy="0 0 0"/>
      <geometry name="FINGER_1_collision_geometry_2">
        <mesh filename="meshes/FINGER_1_2.collision.stl"/>
      </geometry>
    </collision>
    <inertial name="FINGER_1_inertial_2">
      <mass value="0.044318"/>
      <inertia ixx="0.000023" iyy="0.000010" izz="0.000016" ixy="0.000002" ixz="0" iyz="0"/>
      <origin xyz="-0.010671 0.028985 0.018799" rpy="0 0 0"/>
    </inertial>
  </link>
  <link name="FOOT">
    <visual name="FOOT_visual">
      <origin xyz="0 0 0" rpy="0 0 0"/>
      <geometry name="FOOT_geometry">
        <mesh filename="meshes/FOOT.stl"/>
      </geometry>
      <material name="FOOT_material">
        <color rgba="0.627451 0.627451 0.627451 1"/>
      </material>
    </visual>
    <collision name="FOOT.collision">
      <origin xyz="0 0 0" rpy="0 0 0"/>
      <geometry name="FOOT_collision_geometry">
        <mesh filename="meshes/FOOT.collision.stl"/>
      </geometry>
    </collision>
    <inertial name="FOOT_inertial">
      <mass value="0.278140"/>
      <inertia ixx="0.000045" iyy="0.000205" izz="0.000182" ixy="0.000005" ixz="0" iyz="0"/>
      <origin xyz="-0.015078 0.027835 0.018700" rpy="0 0 0"/>
    </inertial>
  </link>
  <link name="FOOT_2">
    <visual name="FOOT_visual_2">
      <origin xyz="0 0 0" rpy="0 0 0"/>
      <geometry name="FOOT_geometry_2">
        <mesh filename="meshes/FOOT_2.stl"/>
      </geometry>
      <material name="FOOT_material_2">
        <color rgba="0.627451 0.627451 0.627451 1"/>
      </material>
    </visual>
    <collision name="FOOT.collision_2">
      <origin xyz="0 0 0" rpy="0 0 0"/>
      <geometry name="FOOT_collision_geometry_2">
        <mesh filename="meshes/FOOT_2.collision.stl"/>
      </geometry>
    </collision>
    <inertial name="FOOT_inertial_2">
      <mass value="0.278140"/>
      <inertia ixx="0.000045" iyy="0.000205" izz="0.000182" ixy="-0.000005" ixz="0" iyz="0"/>
      <origin xyz="-0.015078 -0.027835 0.018700" rpy="0 0 0"/>
    </inertial>
  </link>
</robot>
