<mujoco model="z-bot2_fe_urdf">
  <default>
    <default class="robot">
      <joint limited="true" damping="0.01" armature="0.01" frictionloss="0.01" actuatorfrcrange="-1000 1000" />
      <default class="visual">
        <geom material="visualgeom" contype="0" conaffinity="0" group="2" />
      </default>
      <default class="collision">
        <geom condim="6" conaffinity="15" friction="0.8 0.02 0.01" solimp="0.015 1 0.036" group="3" />
      </default>
    </default>
  </default>

  <compiler angle="radian" meshdir="meshes" />

  <option integrator="implicitfast" cone="elliptic" impratio="100" />

  <visual>
    <global ellipsoidinertia="true" />
  </visual>

  <asset>
    <material name="Z-BOT2_MASTER-BODY-SKELETON_material" rgba="0.494118 0.623529 0.749020 1" />
    <material name="IMU_material" rgba="0 1 0 1" />
    <material name="Z-BOT2-MASTER-SHOULDER2_material" rgba="0.364706 0.360784 0.749020 1" />
    <material name="U-HIP-L_material" rgba="0.768627 0.886275 0.952941 1" />
    <material name="3215_1Flange_material" rgba="0.749020 0.498039 0.725490 1" />
    <material name="3215_BothFlange_material_5" rgba="1 0 0 1" />
    <material name="R-ARM-MIRROR-1_material" rgba="0.647059 0.647059 0.647059 1" />
    <material name="L-ARM-MIRROR_1_material" rgba="0.627451 0.627451 0.627451 1" />
    <material name="default_material" rgba="0.7 0.7 0.7 1" />
    <mesh name="Z-BOT2_MASTER-BODY-SKELETON.collision.stl" file="Z-BOT2_MASTER-BODY-SKELETON.collision.stl" />
    <mesh name="Z-BOT2_MASTER-BODY-SKELETON.stl" file="Z-BOT2_MASTER-BODY-SKELETON.stl" />
    <mesh name="IMU.stl" file="IMU.stl" />
    <mesh name="Z-BOT2-MASTER-SHOULDER2.stl" file="Z-BOT2-MASTER-SHOULDER2.stl" />
    <mesh name="3215_1Flange.collision.stl" file="3215_1Flange.collision.stl" />
    <mesh name="3215_1Flange.stl" file="3215_1Flange.stl" />
    <mesh name="R-ARM-MIRROR-1.collision.stl" file="R-ARM-MIRROR-1.collision.stl" />
    <mesh name="R-ARM-MIRROR-1.stl" file="R-ARM-MIRROR-1.stl" />
    <mesh name="FINGER_1.collision.stl" file="FINGER_1.collision.stl" />
    <mesh name="FINGER_1.stl" file="FINGER_1.stl" />
    <mesh name="Z-BOT2-MASTER-SHOULDER2_2.stl" file="Z-BOT2-MASTER-SHOULDER2_2.stl" />
    <mesh name="3215_1Flange_2.collision.stl" file="3215_1Flange_2.collision.stl" />
    <mesh name="3215_1Flange_2.stl" file="3215_1Flange_2.stl" />
    <mesh name="L-ARM-MIRROR_1.collision.stl" file="L-ARM-MIRROR_1.collision.stl" />
    <mesh name="L-ARM-MIRROR_1.stl" file="L-ARM-MIRROR_1.stl" />
    <mesh name="FINGER_1_2.collision.stl" file="FINGER_1_2.collision.stl" />
    <mesh name="FINGER_1_2.stl" file="FINGER_1_2.stl" />
    <mesh name="U-HIP-L.stl" file="U-HIP-L.stl" />
    <mesh name="3215_BothFlange_5.stl" file="3215_BothFlange_5.stl" />
    <mesh name="3215_BothFlange_9.collision.stl" file="3215_BothFlange_9.collision.stl" />
    <mesh name="3215_BothFlange_9.stl" file="3215_BothFlange_9.stl" />
    <mesh name="3215_BothFlange_13.collision.stl" file="3215_BothFlange_13.collision.stl" />
    <mesh name="3215_BothFlange_13.stl" file="3215_BothFlange_13.stl" />
    <mesh name="FOOT.collision.stl" file="FOOT.collision.stl" />
    <mesh name="FOOT.stl" file="FOOT.stl" />
    <mesh name="U-HIP-R.stl" file="U-HIP-R.stl" />
    <mesh name="3215_BothFlange_6.stl" file="3215_BothFlange_6.stl" />
    <mesh name="3215_BothFlange_10.collision.stl" file="3215_BothFlange_10.collision.stl" />
    <mesh name="3215_BothFlange_10.stl" file="3215_BothFlange_10.stl" />
    <mesh name="3215_BothFlange_14.collision.stl" file="3215_BothFlange_14.collision.stl" />
    <mesh name="3215_BothFlange_14.stl" file="3215_BothFlange_14.stl" />
    <mesh name="FOOT_2.collision.stl" file="FOOT_2.collision.stl" />
    <mesh name="FOOT_2.stl" file="FOOT_2.stl" />
  </asset>

  <worldbody>
    <body name="Z-BOT2_MASTER-BODY-SKELETON" pos="0.00000000 0.00000000 0.41738402" childclass="robot">
      <freejoint name="floating_base" />
      <geom name="Z-BOT2_MASTER-BODY-SKELETON_collision" type="mesh" mesh="Z-BOT2_MASTER-BODY-SKELETON.collision.stl" class="collision" />
      <geom name="Z-BOT2_MASTER-BODY-SKELETON_visual" material="Z-BOT2_MASTER-BODY-SKELETON_material" type="mesh" mesh="Z-BOT2_MASTER-BODY-SKELETON.stl" class="visual" />
      <body name="Z-BOT2-MASTER-SHOULDER2" pos="0.060002 -0.011000 -0.010001" quat="0.0005633121735972125 0.0005628637715330792 -0.7068249569936026 -0.707388044876899">
        <joint name="left_shoulder_yaw" type="hinge" range="-1.047198 0" axis="0 0 1" />
        <inertial pos="-0.012788 0.001374 0.018800" mass="0.024098" diaginertia="7e-06 8e-06 3e-06" />
        <geom name="Z-BOT2-MASTER-SHOULDER2_visual" material="Z-BOT2-MASTER-SHOULDER2_material" type="mesh" mesh="Z-BOT2-MASTER-SHOULDER2.stl" class="visual" />
        <body name="3215_1Flange" pos="-0.020845 -0.004900 0.018800" quat="0.5000001633974483 -0.4999999999999733 0.49999983660255165 -0.4999999999999733">
          <joint name="left_shoulder_pitch" type="hinge" range="-2.967060 3.141593" axis="0 0 1" />
          <inertial pos="0.033642 0.000438 -0.019963" mass="0.181960" diaginertia="5.4e-05 0.000228 0.000232" />
          <geom name="3215_1Flange_collision" type="mesh" mesh="3215_1Flange.collision.stl" class="collision" />
          <geom name="3215_1Flange_visual" material="3215_1Flange_material" type="mesh" mesh="3215_1Flange.stl" class="visual" />
          <body name="R-ARM-MIRROR-1" pos="0.092984 0.019800 -0.018600" quat="-1.2247452309842457e-07 -1.22474483074382e-07 0.7071066656470838 0.7071068967259713">
            <joint name="left_elbow" type="hinge" range="-1.570796 1.570796" axis="0 0 -1" />
            <inertial pos="-0.051119 0.001150 -0.017743" mass="0.186073" diaginertia="6.1e-05 0.000218 0.000201" />
            <geom name="R-ARM-MIRROR-1_collision" type="mesh" mesh="R-ARM-MIRROR-1.collision.stl" class="collision" />
            <geom name="R-ARM-MIRROR-1_visual" material="R-ARM-MIRROR-1_material" type="mesh" mesh="R-ARM-MIRROR-1.stl" class="visual" />
            <body name="FINGER_1" pos="-0.066206 -0.011778 0.001260" quat="-9.934637848443371e-08 0.5735765089253517 0.8191519934718928 -1.418813056556475e-07">
              <joint name="left_gripper" type="hinge" range="-0.349066 0.698132" axis="0 0 1" />
              <inertial pos="-0.010671 -0.028985 0.018800" mass="0.044318" diaginertia="2.3e-05 1e-05 1.6e-05" />
              <geom name="FINGER_1_collision" type="mesh" mesh="FINGER_1.collision.stl" class="collision" />
              <geom name="FINGER_1_visual" material="L-ARM-MIRROR_1_material" type="mesh" mesh="FINGER_1.stl" class="visual" />
            </body>
          </body>
        </body>
      </body>
      <body name="Z-BOT2-MASTER-SHOULDER2_2" pos="-0.060000 -0.011000 -0.010001" quat="0.7073882691671998 -0.706825181105366 0.0 0.0">
        <joint name="right_shoulder_yaw" type="hinge" range="0 1.047198" axis="0 0 1" />
        <inertial pos="-0.012788 -0.001374 0.018800" mass="0.024098" diaginertia="7e-06 8e-06 3e-06" />
        <geom name="Z-BOT2-MASTER-SHOULDER2_2_visual" material="Z-BOT2-MASTER-SHOULDER2_material" type="mesh" mesh="Z-BOT2-MASTER-SHOULDER2_2.stl" class="visual" />
        <body name="3215_1Flange_2" pos="-0.020845 0.004900 0.018800" quat="0.5000001633974483 0.4999999999999733 0.49999983660255165 0.4999999999999733">
          <joint name="right_shoulder_pitch" type="hinge" range="-3.141593 2.967060" axis="0 0 1" />
          <inertial pos="0.033642 -0.000433 -0.019968" mass="0.181960" diaginertia="5.4e-05 0.000228 0.000232" />
          <geom name="3215_1Flange_2_collision" type="mesh" mesh="3215_1Flange_2.collision.stl" class="collision" />
          <geom name="3215_1Flange_2_visual" material="3215_1Flange_material" type="mesh" mesh="3215_1Flange_2.stl" class="visual" />
          <body name="L-ARM-MIRROR_1" pos="0.092984 -0.019800 -0.018600" quat="0.5000001633974483 -0.4999999999999733 -0.4999999999999733 -0.49999983660255165">
            <joint name="right_elbow" type="hinge" range="-1.570796 1.570796" axis="0 0 1" />
            <inertial pos="0.001144 0.051123 0.017764" mass="0.186073" diaginertia="0.000218 6.1e-05 0.000201" />
            <geom name="L-ARM-MIRROR_1_collision" type="mesh" mesh="L-ARM-MIRROR_1.collision.stl" class="collision" />
            <geom name="L-ARM-MIRROR_1_visual" material="L-ARM-MIRROR_1_material" type="mesh" mesh="L-ARM-MIRROR_1.stl" class="visual" />
            <body name="FINGER_1_2" pos="-0.011778 0.066206 -0.001260" quat="0.9848077400232231 0.0 0.0 0.1736482513311082">
              <joint name="right_gripper" type="hinge" range="-0.698132 0.349066" axis="0 0 1" />
              <inertial pos="-0.010671 0.028985 0.018799" mass="0.044318" diaginertia="2.3e-05 1e-05 1.6e-05" />
              <geom name="FINGER_1_2_collision" type="mesh" mesh="FINGER_1_2.collision.stl" class="collision" />
              <geom name="FINGER_1_2_visual" material="L-ARM-MIRROR_1_material" type="mesh" mesh="FINGER_1_2.stl" class="visual" />
            </body>
          </body>
        </body>
      </body>
      <body name="U-HIP-L" pos="0.040000 0.009998 -0.079000" quat="6.341362302272584e-07 0.0007963264582434141 0.9999993658637698 0.0007963264582434141">
        <joint name="left_hip_yaw" type="hinge" range="-1.047198 1.047198" axis="0 0 1" />
        <inertial pos="-0.001161 -0.004396 0.035396" mass="0.047132" diaginertia="2.9e-05 3e-05 1.9e-05" />
        <geom name="U-HIP-L_visual" material="U-HIP-L_material" type="mesh" mesh="U-HIP-L.stl" class="visual" />
        <body name="3215_BothFlange_5" pos="0 0.017700 0.056400" quat="0.7071068967259818 -0.7071066656470943 0.0 0.0">
          <joint name="left_hip_roll" type="hinge" range="-0.174533 1.570796" axis="0 0 -1.0" />
          <inertial pos="0.012332 -0.008997 -0.018508" mass="0.068295" diaginertia="1.9e-05 2.4e-05 2.5e-05" />
          <geom name="3215_BothFlange_5_visual" material="3215_BothFlange_material_5" type="mesh" mesh="3215_BothFlange_5.stl" class="visual" />
          <body name="3215_BothFlange_9" pos="-0.006400 -0.032000 -0.017900" quat="0.5000001633974483 0.4999999999999733 -0.49999983660255165 -0.4999999999999733">
            <joint name="left_hip_pitch" type="hinge" range="-1.570796 1.570796" axis="0 0 1" />
            <inertial pos="0.043662 -0.002857 -0.018525" mass="0.143337" diaginertia="4.9e-05 0.000148 0.000128" />
            <geom name="3215_BothFlange_9_collision" type="mesh" mesh="3215_BothFlange_9.collision.stl" class="collision" />
            <geom name="3215_BothFlange_9_visual" material="3215_BothFlange_material_5" type="mesh" mesh="3215_BothFlange_9.stl" class="visual" />
            <body name="3215_BothFlange_13" pos="0.100000 0.010000 -0.001260">
              <joint name="left_knee" type="hinge" range="-1.221731 2.792527" axis="0 0 1" />
              <inertial pos="0.050000 0 -0.017988" mass="0.128213" diaginertia="3.5e-05 0.000154 0.000145" />
              <geom name="3215_BothFlange_13_collision" type="mesh" mesh="3215_BothFlange_13.collision.stl" class="collision" />
              <geom name="3215_BothFlange_13_visual" material="3215_BothFlange_material_5" type="mesh" mesh="3215_BothFlange_13.stl" class="visual" />
              <body name="FOOT" pos="0.100000 0 0.000800" quat="-1.2247452309842457e-07 -0.7071068967259713 -0.7071066656470838 -1.22474483074382e-07">
                <joint name="left_ankle" type="hinge" range="-1.570796 1.570796" axis="0 0 1" />
                <inertial pos="-0.015078 0.027835 0.018700" mass="0.278140" diaginertia="4.5e-05 0.000205 0.000182" />
                <geom name="FOOT_collision" type="mesh" mesh="FOOT.collision.stl" class="collision" />
                <geom name="FOOT_visual" material="L-ARM-MIRROR_1_material" type="mesh" mesh="FOOT.stl" class="visual" />
              </body>
            </body>
          </body>
        </body>
      </body>
      <body name="U-HIP-R" pos="-0.040000 0.009998 -0.079000" quat="6.341362302272584e-07 0.0007963264582434141 0.9999993658637698 0.0007963264582434141">
        <joint name="right_hip_yaw" type="hinge" range="-1.047198 1.047198" axis="0 0 1" />
        <inertial pos="0.001161 -0.004396 0.035396" mass="0.047132" diaginertia="2.9e-05 3e-05 1.9e-05" />
        <geom name="U-HIP-R_visual" material="U-HIP-L_material" type="mesh" mesh="U-HIP-R.stl" class="visual" />
        <body name="3215_BothFlange_6" pos="0 -0.017700 0.056400" quat="-1.2247452309842457e-07 1.22474483074382e-07 0.7071066656470838 -0.7071068967259713">
          <joint name="right_hip_roll" type="hinge" range="-1.570796 0.174533" axis="0 0 1" />
          <inertial pos="0.012332 -0.008983 -0.017811" mass="0.068295" diaginertia="1.9e-05 2.4e-05 2.5e-05" />
          <geom name="3215_BothFlange_6_visual" material="3215_BothFlange_material_5" type="mesh" mesh="3215_BothFlange_6.stl" class="visual" />
          <body name="3215_BothFlange_10" pos="-0.006400 -0.032000 -0.018900" quat="0.5000001633974483 0.4999999999999733 -0.49999983660255165 -0.4999999999999733">
            <joint name="right_hip_pitch" type="hinge" range="-1.570796 1.570796" axis="0 0 1" />
            <inertial pos="0.043662 0.002863 -0.018537" mass="0.143337" diaginertia="4.9e-05 0.000148 0.000128" />
            <geom name="3215_BothFlange_10_collision" type="mesh" mesh="3215_BothFlange_10.collision.stl" class="collision" />
            <geom name="3215_BothFlange_10_visual" material="3215_BothFlange_material_5" type="mesh" mesh="3215_BothFlange_10.stl" class="visual" />
            <body name="3215_BothFlange_14" pos="0.100000 -0.010000 -0.001260">
              <joint name="right_knee" type="hinge" range="-2.792527 1.221731" axis="0 0 1" />
              <inertial pos="0.050000 0 -0.017888" mass="0.128213" diaginertia="3.6e-05 0.000155 0.000145" />
              <geom name="3215_BothFlange_14_collision" type="mesh" mesh="3215_BothFlange_14.collision.stl" class="collision" />
              <geom name="3215_BothFlange_14_visual" material="3215_BothFlange_material_5" type="mesh" mesh="3215_BothFlange_14.stl" class="visual" />
              <body name="FOOT_2" pos="0.100000 0 0.001000" quat="-1.2247452309842457e-07 -0.7071068967259713 0.7071066656470838 1.22474483074382e-07">
                <joint name="right_ankle" type="hinge" range="-1.570796 1.570796" axis="0 0 1" />
                <inertial pos="-0.015078 -0.027835 0.018700" mass="0.278140" diaginertia="4.5e-05 0.000205 0.000182" />
                <geom name="FOOT_2_collision" type="mesh" mesh="FOOT_2.collision.stl" class="collision" />
                <geom name="FOOT_2_visual" material="L-ARM-MIRROR_1_material" type="mesh" mesh="FOOT_2.stl" class="visual" />
              </body>
            </body>
          </body>
        </body>
      </body>
      <site name="Z-BOT2_MASTER-BODY-SKELETON_site" />
      <site name="IMU" pos="0.041000 0.010001 -0.030001" quat="0.5003981633553667 0.49999984146591736 -0.49960183664463337 -0.49999984146591736" />
    </body>
  </worldbody>

  <actuator>
    <position name="left_shoulder_yaw_ctrl" joint="left_shoulder_yaw" kp="100.00000000" kv="10.00000000" forcerange="-2.00000000 2.00000000" forcelimited="true" ctrlrange="-1.047198 0.0" ctrllimited="true" class="robot" />
    <position name="left_shoulder_pitch_ctrl" joint="left_shoulder_pitch" kp="100.00000000" kv="10.00000000" forcerange="-2.00000000 2.00000000" forcelimited="true" ctrlrange="-2.96706 3.141593" ctrllimited="true" class="robot" />
    <position name="left_elbow_ctrl" joint="left_elbow" kp="100.00000000" kv="10.00000000" forcerange="-2.00000000 2.00000000" forcelimited="true" ctrlrange="-1.570796 1.570796" ctrllimited="true" class="robot" />
    <position name="left_gripper_ctrl" joint="left_gripper" kp="100.00000000" kv="10.00000000" forcerange="-2.00000000 2.00000000" forcelimited="true" ctrlrange="-0.349066 0.698132" ctrllimited="true" class="robot" />
    <position name="right_shoulder_yaw_ctrl" joint="right_shoulder_yaw" kp="100.00000000" kv="10.00000000" forcerange="-2.00000000 2.00000000" forcelimited="true" ctrlrange="0.0 1.047198" ctrllimited="true" class="robot" />
    <position name="right_shoulder_pitch_ctrl" joint="right_shoulder_pitch" kp="100.00000000" kv="10.00000000" forcerange="-2.00000000 2.00000000" forcelimited="true" ctrlrange="-3.141593 2.96706" ctrllimited="true" class="robot" />
    <position name="right_elbow_ctrl" joint="right_elbow" kp="100.00000000" kv="10.00000000" forcerange="-2.00000000 2.00000000" forcelimited="true" ctrlrange="-1.570796 1.570796" ctrllimited="true" class="robot" />
    <position name="right_gripper_ctrl" joint="right_gripper" kp="100.00000000" kv="10.00000000" forcerange="-2.00000000 2.00000000" forcelimited="true" ctrlrange="-0.698132 0.349066" ctrllimited="true" class="robot" />
    <position name="left_hip_yaw_ctrl" joint="left_hip_yaw" kp="100.00000000" kv="10.00000000" forcerange="-2.00000000 2.00000000" forcelimited="true" ctrlrange="-1.047198 1.047198" ctrllimited="true" class="robot" />
    <position name="left_hip_roll_ctrl" joint="left_hip_roll" kp="100.00000000" kv="10.00000000" forcerange="-2.00000000 2.00000000" forcelimited="true" ctrlrange="-0.174533 1.570796" ctrllimited="true" class="robot" />
    <position name="left_hip_pitch_ctrl" joint="left_hip_pitch" kp="100.00000000" kv="10.00000000" forcerange="-2.00000000 2.00000000" forcelimited="true" ctrlrange="-1.570796 1.570796" ctrllimited="true" class="robot" />
    <position name="left_knee_ctrl" joint="left_knee" kp="100.00000000" kv="10.00000000" forcerange="-2.00000000 2.00000000" forcelimited="true" ctrlrange="-1.221731 2.792527" ctrllimited="true" class="robot" />
    <position name="left_ankle_ctrl" joint="left_ankle" kp="100.00000000" kv="10.00000000" forcerange="-2.00000000 2.00000000" forcelimited="true" ctrlrange="-1.570796 1.570796" ctrllimited="true" class="robot" />
    <position name="right_hip_yaw_ctrl" joint="right_hip_yaw" kp="100.00000000" kv="10.00000000" forcerange="-2.00000000 2.00000000" forcelimited="true" ctrlrange="-1.047198 1.047198" ctrllimited="true" class="robot" />
    <position name="right_hip_roll_ctrl" joint="right_hip_roll" kp="100.00000000" kv="10.00000000" forcerange="-2.00000000 2.00000000" forcelimited="true" ctrlrange="-1.570796 0.174533" ctrllimited="true" class="robot" />
    <position name="right_hip_pitch_ctrl" joint="right_hip_pitch" kp="100.00000000" kv="10.00000000" forcerange="-2.00000000 2.00000000" forcelimited="true" ctrlrange="-1.570796 1.570796" ctrllimited="true" class="robot" />
    <position name="right_knee_ctrl" joint="right_knee" kp="100.00000000" kv="10.00000000" forcerange="-2.00000000 2.00000000" forcelimited="true" ctrlrange="-2.792527 1.221731" ctrllimited="true" class="robot" />
    <position name="right_ankle_ctrl" joint="right_ankle" kp="100.00000000" kv="10.00000000" forcerange="-2.00000000 2.00000000" forcelimited="true" ctrlrange="-1.570796 1.570796" ctrllimited="true" class="robot" />
  </actuator>

  <contact>
    <exclude body1="3215_1Flange" body2="R-ARM-MIRROR-1" />
    <exclude body1="3215_1Flange_2" body2="L-ARM-MIRROR_1" />
    <exclude body1="3215_BothFlange_9" body2="3215_BothFlange_13" />
    <exclude body1="3215_BothFlange_10" body2="3215_BothFlange_14" />
    <exclude body1="R-ARM-MIRROR-1" body2="FINGER_1" />
    <exclude body1="L-ARM-MIRROR_1" body2="FINGER_1_2" />
    <exclude body1="3215_BothFlange_13" body2="FOOT" />
    <exclude body1="3215_BothFlange_14" body2="FOOT_2" />
  </contact>

  <sensor>
    <accelerometer name="IMU_acc" site="IMU" noise="0.01" />
    <gyro name="IMU_gyro" site="IMU" noise="0.01" />
    <magnetometer name="IMU_mag" site="IMU" noise="0.05" />
    <framepos name="base_link_pos" objtype="site" objname="IMU" />
    <framequat name="base_link_quat" objtype="site" objname="IMU" />
    <framelinvel name="base_link_vel" objtype="site" objname="IMU" />
    <frameangvel name="base_link_ang_vel" objtype="site" objname="IMU" />
  </sensor>
</mujoco>